Workbook

Sheet PRAGATHI
A1: PRAGATHI, Tirupati
A2: Report for the month of: May-2025
A3: Sl. No. | B3: Indicator | C3: Achievement during the month
B4: Education:
A5: 1 | B5: Number of dropout mainstreamed(6-14 years ) | C5: 0
A6: 2 | B6: Numbe of Dropout Mainstreamed (15-18 years ) | C6: 0
A7: 3 | B7: Number of children received education scholarship | C7: 0
A8: 4 | B8: Number of children appeared for Instant or Supplementary exams (10th and Intermediate) | C8: 102 | D8: Boys-52, Girls-50
A9: 5 | B9: Number of children received "Transport Allowance" to attend the school | C9: 0
A10: 6 | B10: Number of children provided with "free bus pass" | C10: 0
A11: 7 | B11: Number of children received free bicycles from the government | C11: 0
B12: School-related indicators:
A13: 8 | B13: Number of schools where additional teachers were appointed | C13: 0
A14: 9 | B14: Number of additional teachers appointed | C14: 0
A15: 10 | B15: Number of schools where new class-rooms were constructed | C15: 0
A16: 11 | B16: Number of schools where new toilets are constructed | C16: 0
A17: 12 | B17: Number of schools where drinking water facilities was created within the premises | C17: 0
A18: 13 | B18: Number of schools where new kitchen shed was constructed | C18: 0
A19: 14 | B19: Number of schools where new ramp was constructed | C19: 0
A20: 15 | B20: Number of schools where play ground facility was created | C20: 0
A21: 16 | B21: Number of schools prevented from closure | C21: 0
A22: 17 | B22: Number of schools upgraded | C22: 0
A23: 18 | B23: Number of schools where class upgradation happened | C23: 0
A24: 19 | B24: Number of ICDS centres which got new buildings (own) | C24: 0
A25: 20 | B25: Number of children admitted into Pre-school of Anganwadi | C25: 16 | D25: 9 Boys and 7 Girls
A26: 21 | B26: No of CBO/ Parents/ SMC meetings conducted | C26: 77 | D26: CBO Meetings-38,Parents Meetings-39, SMC-0
B27: Protection:
A28: 22 | B28: Number of New CL identified (6-14) | C28: 0
A29: 23 | B29: Number of New CL identified (15-18) | C29: 0
A30: 24 | B30: Number of CL rescued with the support from the Police and Labour Departments | C30: 0
A31: 25 | B31: No of CL removed from work using Couselling, home visits, through the support of CBOs, VCPCs PRIs etc. (6-14 Years ) | C31: 2 | D31: 1 Boy and 1 Girl
A32: 26 | B32: No of CL removed from work using Couselling, home visits, through the support of CBOs, VCPCs PRIs etc. (15-18 Years ) | C32: 8 | D32: 5 Boys and 3 Girls
A33: 27 | B33: Number of child labour mainstreamed(6-14) | C33: 0
A34: 28 | B34: Number of CL manstreamed (15-18) | C34: 0
A35: 29 | B35: Number of Birth Certificates issued to 0-1 year children | C35: 10 | D35: 5 Boys and 5 Girls
A36: 30 | B36: Number of Caste Certificates issued to children | C36: 62 | D36: 28 Boys and 34 Girls
A37: 31 | B37: Number of AADHAR cards issued to children | C37: 29 | D37: 18 Boys and 11 Girls
A38: 32 | B38: No. of VCPC Meetings Conducted in the existing Committees | C38: 5 | D38: Kandadu, Chelluru, MD Puttur, RV Kandriga, Chennampalli,
A39: 33 | B39: Number of Child Protection Committees formed at Village-level (under ICPS) | C39: 0
A40: 34 | B40: Number of child marriages averted | C40: 8 | D40: 8 Girls
...

Sheet SRAMA
A1: Project: SRAMA
A2: Report for the month of: May 2025
A3: Sl. No. | B3: Indicator | C3: Achievement during the month
B4: Education:
A5: 1 | B5: Number of dropout mainstreamed(6-14 years ) | C5: 0
A6: 2 | B6: Numbe of Dropout Mainstreamed (15-18 years ) | C6: 0
A7: 3 | B7: Number of children received education scholarship | C7: 0
A8: 4 | B8: Number of children appeared for Instant or Supplementary exams (10th and Intermediate) | C8: 33
A9: 5 | B9: Number of children received "Transport Allowance" to attend the school | C9: 0
A10: 6 | B10: Number of children provided with "free bus pass" | C10: 0
A11: 7 | B11: Number of children received free bicycles from the government | C11: 0
B12: School-related indicators:
A13: 8 | B13: Number of schools where additional teachers were appointed | C13: 0
A14: 9 | B14: Number of additional teachers appointed | C14: 0
A15: 10 | B15: Number of schools where new class-rooms were constructed | C15: 0
A16: 11 | B16: Number of schools where new toilets are constructed | C16: 0
A17: 12 | B17: Number of schools where drinking water facilities was created within the premises | C17: 0
A18: 13 | B18: Number of schools where new kitchen shed was constructed | C18: 0
A19: 14 | B19: Number of schools where new ramp was constructed | C19: 0
A20: 15 | B20: Number of schools where play ground facility was created | C20: 0
A21: 16 | B21: Number of schools prevented from closure | C21: 0
A22: 17 | B22: Number of schools upgraded | C22: 0
A23: 18 | B23: Number of schools where class upgradation happened | C23: 0
A24: 19 | B24: Number of ICDS centres which got new buildings (own) | C24: 0
A25: 20 | B25: Number of children admitted into Pre-school of Anganwadi | C25: 5 | D25: Beneficiary Id's: 1385251, 1617392, 1627367, 887422,887420.
A26: 21 | B26: No of CBO/ Parents/ SMC meetings conducted | C26: 12 | D26: Share Break up : 1 CBOs, 11 parents
B27: Protection:
A28: 22 | B28: Number of New CL identified (6-14) | C28: 0
A29: 23 | B29: Number of New CL identified (15-18) | C29: 0
A30: 24 | B30: Number of CL rescued with the support from the Police and Labour Departments | C30: 0
A31: 25 | B31: No of CL removed from work using Couselling, home visits, through the support of CBOs, VCPCs PRIs etc. (6-14 Years ) | C31: 9 | D31: Beneficiary Id's:1131061,1131076, 512516, 885350,514025, 479219, 507769, 472998, 521910
A32: 26 | B32: No of CL removed from work using Couselling, home visits, through the support of CBOs, VCPCs PRIs etc. (15-18 Years ) | C32: 16 | D32: Beneficiary ID's : 507319,474228,512525,883532,524433,1385462,475179,519975,472776,476533, 516718, 514024, 459618, 476764, 510891, 503353,
A33: 27 | B33: Number of child labour mainstreamed(6-14) | C33: 0
A34: 28 | B34: Number of CL manstreamed (15-18) | C34: 0
A35: 29 | B35: Number of Birth Certificates issued to 0-1 year children | C35: 17 | D35: Beneficiary ID's: 1620531, 1620535, 1619934, 1620533, 1619383, 1620540,1619916,1618443,1621402,1619381, 1621515, 1621612, 1628525, 1626432, 1622091, 1621165, 1621153
A36: 30 | B36: Number of Caste Certificates issued to children | C36: 0
A37: 31 | B37: Number of AADHAR cards issued to children | C37: 17 | D37: Beneficiary ID's: 1620531, 1620535, 1619934, 1620533, 1619383, 1620540,1619916,1618443,1621402,1619381, 1621515, 1621612, 1628525, 1626432, 1622091, 1621165, 1621153
A38: 32 | B38: No. of VCPC Meetings Conducted in the existing Committees | C38: 0
A39: 33 | B39: Number of Child Protection Committees formed at Village-level (under ICPS) | C39: 0
A40: 34 | B40: Number of child marriages averted | C40: 9
...

Sheet KDDI
A1: KDDI, Machilipatnam
A2: Report for the month of: May 2025
A3: Sl. No. | B3: Indicator
B4: Education: | C4: Total | D4: Boy | E4: Girl | F4: Remarks
A5: 1 | B5: Number of dropout mainstreamed(6-14 years ) | C5: 0 | D5: 0 | E5: 0
A6: 2 | B6: Numbe of Dropout Mainstreamed (15-18 years ) | C6: 0 | D6: 0 | E6: 0
A7: 3 | B7: Number of children received education scholarship | C7: 0 | D7: 0 | E7: 0
A8: 4 | B8: Number of children appeared for Instant or Supplementary exams (10th and Intermediate) | C8: 0 | D8: 0 | E8: 0
A9: 5 | B9: Number of children received "Transport Allowance" to attend the school | C9: 0 | D9: 0 | E9: 0
A10: 6 | B10: Number of children provided with "free bus pass" | C10: 0 | D10: 0 | E10: 0
A11: 7 | B11: Number of children received free bicycles from the government | C11: 0 | D11: 0 | E11: 0
B12: School-related indicators:
A13: 8 | B13: Number of schools where additional teachers were appointed | C13: 0 | D13: 0 | E13: 0
A14: 9 | B14: Number of additional teachers appointed | C14: 0 | D14: 0 | E14: 0
A15: 10 | B15: Number of schools where new class-rooms were constructed | C15: 0 | D15: 0 | E15: 0
A16: 11 | B16: Number of schools where new toilets are constructed | C16: 0 | D16: 0 | E16: 0
A17: 12 | B17: Number of schools where drinking water facilities was created within the premises | C17: 0 | D17: 0 | E17: 0
A18: 13 | B18: Number of schools where new kitchen shed was constructed | C18: 0 | D18: 0 | E18: 0
A19: 14 | B19: Number of schools where new ramp was constructed | C19: 0 | D19: 0 | E19: 0
A20: 15 | B20: Number of schools where play ground facility was created | C20: 0 | D20: 0 | E20: 0
A21: 16 | B21: Number of schools prevented from closure | C21: 0 | D21: 0 | E21: 0
A22: 17 | B22: Number of schools upgraded | C22: 0 | D22: 0 | E22: 0
A23: 18 | B23: Number of schools where class upgradation happened | C23: 0 | D23: 0 | E23: 0
A24: 19 | B24: Number of ICDS centres which got new buildings (own) | C24: 0 | D24: 0 | E24: 0
A25: 20 | B25: Number of children admitted into Pre-school of Anganwadi | C25: 0 | D25: 0 | E25: 0
A26: 21 | B26: No of CBO/ Parents/ SMC meetings conducted | C26: 7 | F26: This month, 7 CBO meetings were held in 7 villages are Garaladibba,Gialakaladindi,Campbelpeta,Giripuram,Pedapatnam,Kanuru,Kona. A total of 31 people, 16 men and 15 women, participated in these 7 meetings. Topics: The ills of child marriage, admission of children to college, dropout and Child Labour house visits, We also talked about making efforts to write supplementary exams with children who failed in 10th and intermediate.
B27: Protection:
A28: 22 | B28: Number of New CL identified (6-14) | C28: 0 | D28: 0 | E28: 0
A29: 23 | B29: Number of New CL identified (15-18) | C29: 0 | D29: 0 | E29: 0
A30: 24 | B30: Number of CL rescued with the support from the Police and Labour Departments | C30: 0 | D30: 0 | E30: 0
A31: 25 | B31: No of CL removed from work using Couselling, home visits, through the support of CBOs, VCPCs PRIs etc. (6-14 Years ) | C31: 0 | D31: 0 | E31: 0
A32: 26 | B32: No of CL removed from work using Couselling, home visits, through the support of CBOs, VCPCs PRIs etc. (15-18 Years ) | C32: 0 | D32: 0 | E32: 0
A33: 27 | B33: Number of child labour mainstreamed(6-14) | C33: 0 | D33: 0 | E33: 0
A34: 28 | B34: Number of CL manstreamed (15-18) | C34: 0 | D34: 0 | E34: 0
A35: 29 | B35: Number of Birth Certificates issued to 0-1 year children | C35: 0 | D35: 0 | E35: 0
A36: 30 | B36: Number of Caste Certificates issued to children | C36: 2 | D36: 2 | E36: 0 | F36: Gilakaladindi: Karri Mohan Kumar-1572803 Vatapalli Upendra-1277110
A37: 31 | B37: Number of AADHAR cards issued to children | C37: 0 | D37: 0 | E37: 0
A38: 32 | B38: No. of VCPC Meetings Conducted in the existing Committees | C38: 1 | F38: 1 Village Level Child Protection Committee meeting held in Kanuru village this month. Participation: 6 Men & 4 Female VRO,NGO,Secretory,ANM-Female ,MSK-Female, Anganwadi teacher-Female, VO-Female, Students,Panchayath Ward member,Surpench-Female Topic: About VCPC Strengthening, Since a girl was abused in the village, there was talk of stopping such things.
A39: 33 | B39: Number of Child Protection Committees formed at Village-level (under ICPS) | C39: 0
A40: 34 | B40: Number of child marriages averted | C40: 0 | D40: 0 | E40: 0
...

Sheet PORD
A1: Project: PORD
A2: Report for the month of: May, 2025
A3: SI. No. | B3: Indicator | C3: Achievement During the month
B4: Education:
A5: 1 | B5: Number of dropout mainstreamed(6-14 years ) | C5: 0
A6: 2 | B6: Numbe of Dropout Mainstreamed (15-18 years ) | C6: 0
A7: 3 | B7: Number of children received education scholarship | C7: 0
A8: 4 | B8: Number of children appeared for Instant or Supplementary exams (10th and Intermediate 2nd Year) | C8: =105+46 -> 151 | D8: 60 boys and 45 girls in 10th class. 26 boys and 20 girls in intermediate. 100% failed children appeared for supplementary exams in May.
A9: 5 | B9: Number of children received "Transport Allowance" to attend the school | C9: 0
A10: 6 | B10: Number of children provided with "free bus pass" | C10: 0
A11: 7 | B11: Number of children received free bicycles from the government | C11: 0
B12: School-related indicators:
A13: 8 | B13: Number of schools where additional teachers were appointed | C13: 0
A14: 9 | B14: Number of additional teachers appointed | C14: 0
A15: 10 | B15: Number of schools where new class-rooms were constructed | C15: 0
A16: 11 | B16: Number of schools where new toilets are constructed | C16: 0
A17: 12 | B17: Number of schools where drinking water facilities was created within the premises | C17: 0
A18: 13 | B18: Number of schools where new kitchen shed was constructed | C18: 0
A19: 14 | B19: Number of schools where new ramp was constructed | C19: 0
A20: 15 | B20: Number of schools where play ground facility was created | C20: 0
A21: 16 | B21: Number of schools prevented from closure | C21: 0
A22: 17 | B22: Number of schools upgraded | C22: 0
A23: 18 | B23: Number of schools where class upgradation happened | C23: 0
A24: 19 | B24: Number of ICDS centres which got new buildings (own) | C24: 0
A25: 20 | B25: Number of children admitted into Pre-school of Anganwadi | C25: 0
A26: 21 | B26: No of CBO/ Parents/ SMC meetings conducted | C26: 43 | D26: (43 CBO meetings: 620 (Male:279, Female:341))
B27: Protection:
A28: 22 | B28: Number of New CL identified (6-14) | C28: 0
A29: 23 | B29: Number of New CL identified (15-18) | C29: 0
A30: 24 | B30: Number of CL rescued with the support from the Police and Labour Departments | C30: 0
A31: 25 | B31: No of CL removed from work using Couselling, home visits, through the support of CBOs, VCPCs PRIs etc. (6-14 Years ) | C31: 4 | D31: 4=(Boys:1, Girls:3)
A32: 26 | B32: No of CL removed from work using Couselling, home visits, through the support of CBOs, VCPCs PRIs etc. (15-18 Years ) | C32: 13 | D32: 13=(Boys9: Girls:4)
A33: 27 | B33: Number of child labour mainstreamed(6-14) | C33: 0
A34: 28 | B34: Number of CL manstreamed (15-18) | C34: 0
A35: 29 | B35: Number of Birth Certificates issued to 0-1 year children | C35: 0
A36: 30 | B36: Number of Caste Certificates issued to children | C36: 139 | D36: 139(Boys: 68, Girls:71)
A37: 31 | B37: Number of AADHAR cards issued to children | C37: 0
A38: 32 | B38: No. of VCPC Meetings Conducted in the existing Committees | C38: 0
A39: 33 | B39: Number of Child Protection Committees formed at Village-level (under ICPS) | C39: 0
A40: 34 | B40: Number of child marriages averted | C40: 0
...

Sheet AP
A1: Projects: PRAGATHI, SRAMA, KDDI and PORD
A2: Report for the month of: May 2025
A3: Sl. No. | B3: Indicator | C3: May Month Achievement
B4: Education: | C4: PRAGATHI | D4: SRAMA | E4: KDDI | F4: PORD | G4: Total
A5: 1 | B5: Number of dropout mainstreamed(6-14 years ) | C5: =PRAGATHI!C5 -> 0 | D5: =SRAMA!C5 -> 0 | E5: =KDDI!C5 -> 0 | F5: =PORD!C5 -> 0 | G5: =SUM(C5:F5) -> 0
A6: 2 | B6: Numbe of Dropout Mainstreamed (15-18 years ) | C6: =PRAGATHI!C6 -> 0 | D6: =SRAMA!C6 -> 0 | E6: =KDDI!C6 -> 0 | F6: =PORD!C6 -> 0 | G6: =SUM(C6:F6) -> 0
A7: 3 | B7: Number of children received education scholarship | C7: =PRAGATHI!C7 -> 0 | D7: =SRAMA!C7 -> 0 | E7: =KDDI!C7 -> 0 | F7: =PORD!C7 -> 0 | G7: =SUM(C7:F7) -> 0
A8: 4 | B8: Number of children appeared for Instant or Supplementary exams (10th and Intermediate) | C8: =PRAGATHI!C8 -> 102 | D8: =SRAMA!C8 -> 33 | E8: =KDDI!C8 -> 0 | F8: =PORD!C8 -> 151 | G8: =SUM(C8:F8) -> 286
A9: 5 | B9: Number of children received "Transport Allowance" to attend the school | C9: =PRAGATHI!C9 -> 0 | D9: =SRAMA!C9 -> 0 | E9: =KDDI!C9 -> 0 | F9: =PORD!C9 -> 0 | G9: =SUM(C9:F9) -> 0
A10: 6 | B10: Number of children provided with "free bus pass" | C10: =PRAGATHI!C10 -> 0 | D10: =SRAMA!C10 -> 0 | E10: =KDDI!C10 -> 0 | F10: =PORD!C10 -> 0 | G10: =SUM(C10:F10) -> 0
A11: 7 | B11: Number of children received free bicycles from the government | C11: =PRAGATHI!C11 -> 0 | D11: =SRAMA!C11 -> 0 | E11: =KDDI!C11 -> 0 | F11: =PORD!C11 -> 0 | G11: =SUM(C11:F11) -> 0
B12: School-related indicators:
A13: 8 | B13: Number of schools where additional teachers were appointed | C13: =PRAGATHI!C13 -> 0 | D13: =SRAMA!C13 -> 0 | E13: =KDDI!C13 -> 0 | F13: =PORD!C13 -> 0 | G13: =SUM(C13:F13) -> 0
A14: 9 | B14: Number of additional teachers appointed | C14: =PRAGATHI!C14 -> 0 | D14: =SRAMA!C14 -> 0 | E14: =KDDI!C14 -> 0 | F14: =PORD!C14 -> 0 | G14: =SUM(C14:F14) -> 0
A15: 10 | B15: Number of schools where new class-rooms were constructed | C15: =PRAGATHI!C15 -> 0 | D15: =SRAMA!C15 -> 0 | E15: =KDDI!C15 -> 0 | F15: =PORD!C15 -> 0 | G15: =SUM(C15:F15) -> 0
A16: 11 | B16: Number of schools where new toilets are constructed | C16: =PRAGATHI!C16 -> 0 | D16: =SRAMA!C16 -> 0 | E16: =KDDI!C16 -> 0 | F16: =PORD!C16 -> 0 | G16: =SUM(C16:F16) -> 0
A17: 12 | B17: Number of schools where drinking water facilities was created within the premises | C17: =PRAGATHI!C17 -> 0 | D17: =SRAMA!C17 -> 0 | E17: =KDDI!C17 -> 0 | F17: =PORD!C17 -> 0 | G17: =SUM(C17:F17) -> 0
A18: 13 | B18: Number of schools where new kitchen shed was constructed | C18: =PRAGATHI!C18 -> 0 | D18: =SRAMA!C18 -> 0 | E18: =KDDI!C18 -> 0 | F18: =PORD!C18 -> 0 | G18: =SUM(C18:F18) -> 0
A19: 14 | B19: Number of schools where new ramp was constructed | C19: =PRAGATHI!C19 -> 0 | D19: =SRAMA!C19 -> 0 | E19: =KDDI!C19 -> 0 | F19: =PORD!C19 -> 0 | G19: =SUM(C19:F19) -> 0
A20: 15 | B20: Number of schools where play ground facility was created | C20: =PRAGATHI!C20 -> 0 | D20: =SRAMA!C20 -> 0 | E20: =KDDI!C20 -> 0 | F20: =PORD!C20 -> 0 | G20: =SUM(C20:F20) -> 0
A21: 16 | B21: Number of schools prevented from closure | C21: =PRAGATHI!C21 -> 0 | D21: =SRAMA!C21 -> 0 | E21: =KDDI!C21 -> 0 | F21: =PORD!C21 -> 0 | G21: =SUM(C21:F21) -> 0
A22: 17 | B22: Number of schools upgraded | C22: =PRAGATHI!C22 -> 0 | D22: =SRAMA!C22 -> 0 | E22: =KDDI!C22 -> 0 | F22: =PORD!C22 -> 0 | G22: =SUM(C22:F22) -> 0
A23: 18 | B23: Number of schools where class upgradation happened | C23: =PRAGATHI!C23 -> 0 | D23: =SRAMA!C23 -> 0 | E23: =KDDI!C23 -> 0 | F23: =PORD!C23 -> 0 | G23: =SUM(C23:F23) -> 0
A24: 19 | B24: Number of ICDS centres which got new buildings (own) | C24: =PRAGATHI!C24 -> 0 | D24: =SRAMA!C24 -> 0 | E24: =KDDI!C24 -> 0 | F24: =PORD!C24 -> 0 | G24: =SUM(C24:F24) -> 0
... A26: 21 | B26: No of CBO/ Parents/ SMC meetings conducted | C26: =PRAGATHI!C26 -> 77 | D26: =SRAMA!C26 -> 12 | E26: =KDDI!C26 -> 7 | F26: =PORD!C26 -> 43 | G26: =SUM(C26:F26) -> 139
B27: Protection:
A28: 22 | B28: Number of New CL identified (6-14) | C28: =PRAGATHI!C28 -> 0 | D28: =SRAMA!C28 -> 0 | E28: =KDDI!C28 -> 0 | F28: =PORD!C28 -> 0 | G28: =SUM(C28:F28) -> 0
A29: 23 | B29: Number of New CL identified (15-18) | C29: =PRAGATHI!C29 -> 0 | D29: =SRAMA!C29 -> 0 | E29: =KDDI!C29 -> 0 | F29: =PORD!C29 -> 0 | G29: =SUM(C29:F29) -> 0
A30: 24 | B30: Number of CL rescued with the support from the Police and Labour Departments | C30: =PRAGATHI!C30 -> 0 | D30: =SRAMA!C30 -> 0 | E30: =KDDI!C30 -> 0 | F30: =PORD!C30 -> 0 | G30: =SUM(C30:F30) -> 0
A31: 25 | B31: No of CL removed from work using Couselling, home visits, through the support of CBOs, VCPCs PRIs etc. (6-14 Years ) | C31: =PRAGATHI!C31 -> 2 | D31: =SRAMA!C31 -> 9 | E31: =KDDI!C31 -> 0 | F31: =PORD!C31 -> 4 | G31: =SUM(C31:F31) -> 15
A32: 26 | B32: No of CL removed from work using Couselling, home visits, through the support of CBOs, VCPCs PRIs etc. (15-18 Years ) | C32: =PRAGATHI!C32 -> 8 | D32: =SRAMA!C32 -> 16 | E32: =KDDI!C32 -> 0 | F32: =PORD!C32 -> 13 | G32: =SUM(C32:F32) -> 37
A33: 27 | B33: Number of child labour mainstreamed(6-14) | C33: =PRAGATHI!C33 -> 0 | D33: =SRAMA!C33 -> 0 | E33: =KDDI!C33 -> 0 | F33: =PORD!C33 -> 0 | G33: =SUM(C33:F33) -> 0
A34: 28 | B34: Number of CL manstreamed (15-18) | C34: =PRAGATHI!C34 -> 0 | D34: =SRAMA!C34 -> 0 | E34: =KDDI!C34 -> 0 | F34: =PORD!C34 -> 0 | G34: =SUM(C34:F34) -> 0
A35: 29 | B35: Number of Birth Certificates issued to 0-1 year children | C35: =PRAGATHI!C35 -> 10 | D35: =SRAMA!C35 -> 17 | E35: =KDDI!C35 -> 0 | F35: =PORD!C35 -> 0 | G35: =SUM(C35:F35) -> 27
A36: 30 | B36: Number of Caste Certificates issued to children | C36: =PRAGATHI!C36 -> 62 | D36: =SRAMA!C36 -> 0 | E36: =KDDI!C36 -> 2 | F36: =PORD!C36 -> 139 | G36: =SUM(C36:F36) -> 203
A37: 31 | B37: Number of AADHAR cards issued to children | C37: =PRAGATHI!C37 -> 29 | D37: =SRAMA!C37 -> 17 | E37: =KDDI!C37 -> 0 | F37: =PORD!C37 -> 0 | G37: =SUM(C37:F37) -> 46
A38: 32 | B38: No. of VCPC Meetings Conducted in the existing Committees | C38: =PRAGATHI!C38 -> 5 | D38: =SRAMA!C38 -> 0 | E38: =KDDI!C38 -> 1 | F38: =PORD!C38 -> 0 | G38: =SUM(C38:F38) -> 6
A39: 33 | B39: Number of Child Protection Committees formed at Village-level (under ICPS) | C39: =PRAGATHI!C39 -> 0 | D39: =SRAMA!C39 -> 0 | E39: =KDDI!C39 -> 0 | F39: =PORD!C39 -> 0 | G39: =SUM(C39:F39) -> 0
... A42: 36 | B42: Number of Child Marriages Stopped But happened | C42: =PRAGATHI!C42 -> 0 | D42: =SRAMA!C42 -> 2 | E42: =KDDI!C42 -> 1 | F42: =PORD!C42 -> 0 | G42: =SUM(C42:F42) -> 3
B43: Participation:
...

Sheet EFFORT KMM
A1: Name Of the Partner: EFFORT Report for the month of: May ,2025
A3: S. No. | B3: Indicator | C3: Achievement during the month
B4: Education: | C4: M | D4: F | E4: T
A5: 1 | B5: Number of dropout mainstreamed(6-14 years ) | C5: 0 | D5: 0 | E5: 0 | F5: =E5 -> 0
A6: 2 | B6: Number of Dropout Mainstreamed (15-18 years ) | C6: 0 | D6: 0 | E6: 0 | F6: =E6 -> 0
A7: 3 | B7: Number of children received education scholarship | C7: 0 | D7: 0 | E7: 0 | F7: =E7 -> 0
A8: 4 | B8: Number of children appeared for Instant or Supplementary exams (10th and Intermediate) | C8: 29 | D8: 19 | E8: 48 | F8: =E8 -> 48
A9: 5 | B9: Number of children received "Transport Allowance" to attend the school | C9: 0 | D9: 0 | E9: 0 | F9: =E9 -> 0
A10: 6 | B10: Number of children provided with "free bus pass" | C10: 0 | D10: 0 | E10: 0 | F10: =E10 -> 0
A11: 7 | B11: Number of children received free bicycles from the government | C11: 0 | D11: 0 | E11: 0 | F11: =E11 -> 0
B12: School-related indicators:
A13: 8 | B13: Number of schools where additional teachers were appointed | C13: 0 | F13: 0
A14: 9 | B14: Number of additional teachers appointed | C14: 0 | D14: 0 | E14: 0 | F14: 0
A15: 10 | B15: Number of schools where new class-rooms were constructed | C15: 0 | F15: 0
A16: 11 | B16: Number of schools where new toilets are constructed | C16: 0 | F16: 0
A17: 12 | B17: Number of schools where drinking water facilities was created within the premises | C17: 0 | F17: 0
A18: 13 | B18: Number of schools where new kitchen shed was constructed | C18: 0 | F18: 0
A19: 14 | B19: Number of schools where new ramp was constructed | C19: 0 | F19: 0
A20: 15 | B20: Number of schools where play ground facility was created | C20: 0 | F20: 0
A21: 16 | B21: Number of schools prevented from closure | C21: 0 | F21: 0
A22: 17 | B22: Number of schools upgraded | C22: 0 | F22: 0
A23: 18 | B23: Number of schools where class upgradation happened | C23: 0 | F23: 0
A24: 19 | B24: Number of ICDS centres which got new buildings (own) | C24: 0 | F24: 0
A25: 20 | B25: Number of children admitted into Pre-school of Anganwadi | C25: 0 | D25: 0 | E25: 0 | F25: 0
A26: 21 | B26: No of CBO/ Parents/ SMC meetings conducted ( CBO's -19 ,MM-01 ) | E26: 20 | F26: 20 | G26: CBO's-19 (M-5 , F-291,T-296 ) MM-1(M-0,F-51,T-51)
B27: Protection
A28: 22 | B28: Number of New CL identified (6-14) | C28: 0 | D28: 0 | E28: 0 | F28: =E28 -> 0
A29: 23 | B29: Number of New CL identified (15-18) | C29: 0 | D29: 0 | E29: 0 | F29: =E29 -> 0
A30: 24 | B30: Number of CL rescued with the support from the Police and Labour Departments | C30: 0 | D30: 0 | E30: 0 | F30: =E30 -> 0
A31: 25 | B31: No of CL removed from work using Couselling, home visits, through the support of CBOs, VCPCs PRIs etc. (6-14 Years ) | C31: 0 | D31: 0 | E31: 0 | F31: =E31 -> 0
A32: 26 | B32: No of CL removed from work using Couselling, home visits, through the support of CBOs, VCPCs PRIs etc. (15-18 Years ) | C32: 0 | D32: 0 | E32: 0 | F32: =E32 -> 0
A33: 27 | B33: Number of child labour mainstreamed(6-14) | C33: 0 | D33: 0 | E33: 0 | F33: =E33 -> 0
A34: 28 | B34: Number of CL manstreamed (15-18) | C34: 0 | D34: 0 | E34: 0 | F34: =E34 -> 0
A35: 29 | B35: Number of Birth Certificates issued to 0-1 year children | C35: 0 | D35: 0 | E35: 0 | F35: =E35 -> 0
A36: 30 | B36: Number of Caste Certificates issued to children | C36: 0 | D36: 0 | E36: 0 | F36: =E36 -> 0
A37: 31 | B37: Number of AADHAR cards issued to children | C37: 0 | D37: 0 | E37: 0 | F37: =E37 -> 0
A38: 32 | B38: No. of VCPC Meetings Conducted in the existing Committees (VCPC-2) | E38: 2 | F38: =E38 -> 2 | G38: VCPC-2(M-15,F-27,T-42)
A39: 33 | B39: Number of Child Protection Committees formed at Village-level (under ICPS) | C39: 0 | D39: 0 | E39: 0 | F39: =E39 -> 0
A40: 34 | B40: Number of child marriages averted | C40: 0 | D40: 1 | E40: 1 | F40: =E40 -> 1
A41: 35 | B41: Number of child marriages stopped | C41: 0 | D41: 0 | E41: 0 | F41: =E41 -> 0
...

Sheet EFFORT
A1: Project: EFFORT-Bhadrachalam
A2: Report for the month of: May 2025 | C2: Achievements
A3: Sl. No. | B3: Indicator | C3: Boys | D3: Girls | E3: Total | F3: Remarks
B4: Education:
A5: 1 | B5: Number of Dropout mainstreamed(6-14 years ) | E5: 0
A6: 2 | B6: Numbe of Dropout Mainstreamed (15-18 years ) | E6: 0
A7: 3 | B7: Number of children received education scholarship | E7: 0
A8: 4 | B8: Number of children appeared for Instant or Supplementary exams (10th and Intermediate) | E8: 0
A9: 5 | B9: Number of children received "Transport Allowance" to attend the school | E9: 0
A10: 6 | B10: Number of children provided with "free bus pass" | E10: 0
A11: 7 | B11: Number of children received free bicycles from the government | E11: 0
B12: School-related indicators:
A13: 8 | B13: Number of schools where additional teachers were appointed | E13: 0
A14: 9 | B14: Number of additional teachers appointed | E14: 0
A15: 10 | B15: Number of schools where new class-rooms were constructed | E15: 0
A16: 11 | B16: Number of schools where new toilets are constructed | E16: 0
A17: 12 | B17: Number of schools where drinking water facilities was created within the premises | E17: 0
A18: 13 | B18: Number of schools where new kitchen shed was constructed | E18: 0
A19: 14 | B19: Number of schools where new ramp was constructed | E19: 0
A20: 15 | B20: Number of schools where play ground facility was created | E20: 0
A21: 16 | B21: Number of schools prevented from closure | E21: 0
A22: 17 | B22: Number of schools upgraded | E22: 0
A23: 18 | B23: Number of schools where class upgradation happened | E23: 0
A24: 19 | B24: Number of ICDS centres which got new buildings (own) | E24: 0
... A27: 22 | B27: No.of Parent Module Sessions Conducted | E27: 0
B28: Protection:
A29: 23 | B29: Number of New CL Identified (6-14) | E29: 0
A30: 24 | B30: Number of New CL Identified (15-18) | E30: 0
A31: 25 | B31: Number of CL rescued with the support from the Police and Labour Departments | E31: 0
A32: 26 | B32: No of CL removed from work using Couselling, home visits, through the support of CBOs, VCPCs PRIs etc. (6-14 Years ) | E32: 0
A33: 27 | B33: No of CL removed from work using Couselling, home visits, through the support of CBOs, VCPCs PRIs etc. (15-18 Years ) | E33: 0
A34: 28 | B34: Number of child labour mainstreamed(6-14) | E34: 0
A35: 29 | B35: Number of CL manstreamed (15-18) | E35: 0
A36: 30 | B36: Number of Birth Certificates issued to 0-1 year children | E36: 0
A37: 31 | B37: Number of Caste Certificates issued to children | E37: 0
A38: 32 | B38: Number of AADHAR cards issued to children | E38: 0
A39: 33 | B39: No. of VCPC Meetings Conducted in the existing Committees | E39: 0
A40: 34 | B40: Number of Child Protection Committees formed at Village-level (under ICPS) | E40: 0
... A44: 38 | B44: Number of Child Marriages Stopped But happened | E44: 0
B45: Participation:
...

Sheet MDDI
A1: Project: MDDI
A2: Report for the Month of: MAY 2025
A3: Sl. No. | B3: Indicator | C3: Achievement during the month
B4: Education:
A5: 1 | B5: Number of dropout mainstreamed(6-14 years ) | C5: 0
A6: 2 | B6: Number of Dropout Mainstreamed (15-18 years ) | C6: 0
A7: 3 | B7: Number of children received education scholarship | C7: 0
A8: 4 | B8: Number of children appeared for Instant or Supplementary exams (10th and Intermediate) | C8: 18 | D8: 18 - (11B, 7G) 10th Supplimentary - 14 (9B, 5G) 12th Supplimentary - 4 (2B, 2G)
A9: 5 | B9: Number of children received "Transport Allowance" to attend the school | C9: 0
A10: 6 | B10: Number of children provided with "free bus pass" | C10: 0
A11: 7 | B11: Number of children received free bicycles from the government | C11: 0
B12: School-related indicators:
A13: 8 | B13: Number of schools where additional teachers were appointed | C13: 0
A14: 9 | B14: Number of additional teachers appointed | C14: 0
A15: 10 | B15: Number of schools where new class-rooms were constructed | C15: 0
A16: 11 | B16: Number of schools where new toilets are constructed | C16: 0
A17: 12 | B17: Number of schools where drinking water facilities was created within the premises | C17: 0
A18: 13 | B18: Number of schools where new kitchen shed was constructed | C18: 0
A19: 14 | B19: Number of schools where new ramp was constructed | C19: 0
A20: 15 | B20: Number of schools where play ground facility was created | C20: 0
A21: 16 | B21: Number of schools prevented from closure | C21: 0
A22: 17 | B22: Number of schools upgraded | C22: 0
A23: 18 | B23: Number of schools where class upgradation happened | C23: 0
A24: 19 | B24: Number of ICDS centres which got new buildings (own) | C24: 0
... A26: 21 | B26: No of CBO/ Parents/ SMC meetings conducted | C26: 0
B27: Protection:
A28: 22 | B28: Number of New CL identified (6-14) | C28: 1 | D28: 1B - 6-14 Years
A29: 23 | B29: Number of New CL identified (15-18) | C29: 4 | D29: 4B - 15-18 Years
A30: 24 | B30: Number of CL rescued with the support from the Police and Labour Departments | C30: 0
A31: 25 | B31: No of CL removed from work using Couselling, home visits, through the support of CBOs, VCPCs PRIs etc. (6-14 Years ) | C31: 0
A32: 26 | B32: No of CL removed from work using Couselling, home visits, through the support of CBOs, VCPCs PRIs etc. (15-18 Years ) | C32: 0
A33: 27 | B33: Number of child labour mainstreamed(6-14) | C33: 0
A34: 28 | B34: Number of CL manstreamed (15-18) | C34: 0
A35: 29 | B35: Number of Birth Certificates issued to 0-1 year children | C35: 0
A36: 30 | B36: Number of Caste Certificates issued to children | C36: 4 | D36: Caste Certificates = 4 (2B, 2G) Income Certificates = 5 (2B, 3G)
A37: 31 | B37: Number of AADHAR cards issued to children | C37: 0
A38: 32 | B38: No. of VCPC Meetings Conducted in the existing Committees | C38: 0
A39: 33 | B39: Number of Child Protection Committees formed at Village-level (under ICPS) | C39: 0
A40: 34 | B40: Number of child marriages averted | C40: 0
A41: 35 | B41: Number of child marriages stopped | C41: 0
...

Sheet TG
A1: Projects: EFFORT Kmm, MDDI and EFFORT Bhdracahalm
A2: Report for the month of: May 2025
A3: Sl. No. | B3: Indicator | C3: May Month Achievement
B4: Education: | C4: EFFORT | D4: EFFORT BCM | E4: MDDI | F4: TOTAL
A5: 1 | B5: Number of dropout mainstreamed(6-14 years ) | C5: ='EFFORT KMM'!F5 -> 0 | D5: =EFFORT!E5 -> 0 | E5: =MDDI!C5 -> 0 | F5: =SUM(C5:E5) -> 0
A6: 2 | B6: Number of Dropout Mainstreamed (15-18 years ) | C6: ='EFFORT KMM'!F6 -> 0 | D6: =EFFORT!E6 -> 0 | E6: =MDDI!C6 -> 0 | F6: =SUM(C6:E6) -> 0
A7: 3 | B7: Number of children received education scholarship | C7: ='EFFORT KMM'!F7 -> 0 | D7: =EFFORT!E7 -> 0 | E7: =MDDI!C7 -> 0 | F7: =SUM(C7:E7) -> 0
A8: 4 | B8: Number of children appeared for Instant or Supplementary exams (10th and Intermediate) | C8: ='EFFORT KMM'!F8 -> 48 | D8: =EFFORT!E8 -> 0 | E8: =MDDI!C8 -> 18 | F8: =SUM(C8:E8) -> 66
A9: 5 | B9: Number of children received "Transport Allowance" to attend the school | C9: ='EFFORT KMM'!F9 -> 0 | D9: =EFFORT!E9 -> 0 | E9: =MDDI!C9 -> 0 | F9: =SUM(C9:E9) -> 0
A10: 6 | B10: Number of children provided with "free bus pass" | C10: ='EFFORT KMM'!F10 -> 0 | D10: =EFFORT!E10 -> 0 | E10: =MDDI!C10 -> 0 | F10: =SUM(C10:E10) -> 0
A11: 7 | B11: Number of children received free bicycles from the government | C11: ='EFFORT KMM'!F11 -> 0 | D11: =EFFORT!E11 -> 0 | E11: =MDDI!C11 -> 0 | F11: =SUM(C11:E11) -> 0
B12: School-related indicators:
A13: 8 | B13: Number of schools where additional teachers were appointed | C13: ='EFFORT KMM'!F13 -> 0 | D13: =EFFORT!E13 -> 0 | E13: =MDDI!C13 -> 0 | F13: =SUM(C13:E13) -> 0
A14: 9 | B14: Number of additional teachers appointed | C14: ='EFFORT KMM'!F14 -> 0 | D14: =EFFORT!E14 -> 0 | E14: =MDDI!C14 -> 0 | F14: =SUM(C14:E14) -> 0
A15: 10 | B15: Number of schools where new class-rooms were constructed | C15: ='EFFORT KMM'!F15 -> 0 | D15: =EFFORT!E15 -> 0 | E15: =MDDI!C15 -> 0 | F15: =SUM(C15:E15) -> 0
A16: 11 | B16: Number of schools where new toilets are constructed | C16: ='EFFORT KMM'!F16 -> 0 | D16: =EFFORT!E16 -> 0 | E16: =MDDI!C16 -> 0 | F16: =SUM(C16:E16) -> 0
A17: 12 | B17: Number of schools where drinking water facilities was created within the premises | C17: ='EFFORT KMM'!F17 -> 0 | D17: =EFFORT!E17 -> 0 | E17: =MDDI!C17 -> 0 | F17: =SUM(C17:E17) -> 0
A18: 13 | B18: Number of schools where new kitchen shed was constructed | C18: ='EFFORT KMM'!F18 -> 0 | D18: =EFFORT!E18 -> 0 | E18: =MDDI!C18 -> 0 | F18: =SUM(C18:E18) -> 0
A19: 14 | B19: Number of schools where new ramp was constructed | C19: ='EFFORT KMM'!F19 -> 0 | D19: =EFFORT!E19 -> 0 | E19: =MDDI!C19 -> 0 | F19: =SUM(C19:E19) -> 0
A20: 15 | B20: Number of schools where play ground facility was created | C20: ='EFFORT KMM'!F20 -> 0 | D20: =EFFORT!E20 -> 0 | E20: =MDDI!C20 -> 0 | F20: =SUM(C20:E20) -> 0
A21: 16 | B21: Number of schools prevented from closure | C21: ='EFFORT KMM'!F21 -> 0 | D21: =EFFORT!E21 -> 0 | E21: =MDDI!C21 -> 0 | F21: =SUM(C21:E21) -> 0
A22: 17 | B22: Number of schools upgraded | C22: ='EFFORT KMM'!F22 -> 0 | D22: =EFFORT!E22 -> 0 | E22: =MDDI!C22 -> 0 | F22: =SUM(C22:E22) -> 0
A23: 18 | B23: Number of schools where class upgradation happened | C23: ='EFFORT KMM'!F23 -> 0 | D23: =EFFORT!E23 -> 0 | E23: =MDDI!C23 -> 0 | F23: =SUM(C23:E23) -> 0
A24: 19 | B24: Number of ICDS centres which got new buildings (own) | C24: ='EFFORT KMM'!F24 -> 0 | D24: =EFFORT!E24 -> 0 | E24: =MDDI!C24 -> 0 | F24: =SUM(C24:E24) -> 0
... A26: 21 | B26: No of CBO/ Parents/ SMC meetings conducted | C26: ='EFFORT KMM'!F26 -> 20 | D26: =EFFORT!E26 -> 0 | E26: =MDDI!C26 -> 0 | F26: =SUM(C26:E26) -> 20
B27: Protection:
A28: 22 | B28: Number of New CL identified (6-14) | C28: ='EFFORT KMM'!F28 -> 0 | D28: =EFFORT!E28 -> 0 | E28: =MDDI!C28 -> 1 | F28: =SUM(C28:E28) -> 1
A29: 23 | B29: Number of New CL identified (15-18) | C29: ='EFFORT KMM'!F29 -> 0 | D29: =EFFORT!E29 -> 0 | E29: =MDDI!C29 -> 4 | F29: =SUM(C29:E29) -> 4
A30: 24 | B30: Number of CL rescued with the support from the Police and Labour Departments | C30: ='EFFORT KMM'!F30 -> 0 | D30: =EFFORT!E30 -> 0 | E30: =MDDI!C30 -> 0 | F30: =SUM(C30:E30) -> 0
A31: 25 | B31: No of CL removed from work using Couselling, home visits, through the support of CBOs, VCPCs PRIs etc. (6-14 Years ) | C31: ='EFFORT KMM'!F31 -> 0 | D31: =EFFORT!E31 -> 0 | E31: =MDDI!C31 -> 0 | F31: =SUM(C31:E31) -> 0
A32: 26 | B32: No of CL removed from work using Couselling, home visits, through the support of CBOs, VCPCs PRIs etc. (15-18 Years ) | C32: ='EFFORT KMM'!F32 -> 0 | D32: =EFFORT!E32 -> 0 | E32: =MDDI!C32 -> 0 | F32: =SUM(C32:E32) -> 0
A33: 27 | B33: Number of child labour mainstreamed(6-14) | C33: ='EFFORT KMM'!F33 -> 0 | D33: =EFFORT!E33 -> 0 | E33: =MDDI!C33 -> 0 | F33: =SUM(C33:E33) -> 0
A34: 28 | B34: Number of CL manstreamed (15-18) | C34: ='EFFORT KMM'!F34 -> 0 | D34: =EFFORT!E34 -> 0 | E34: =MDDI!C34 -> 0 | F34: =SUM(C34:E34) -> 0
A35: 29 | B35: Number of Birth Certificates issued to 0-1 year children | C35: ='EFFORT KMM'!F35 -> 0 | D35: =EFFORT!E35 -> 0 | E35: =MDDI!C35 -> 0 | F35: =SUM(C35:E35) -> 0
A36: 30 | B36: Number of Caste Certificates issued to children | C36: ='EFFORT KMM'!F36 -> 0 | D36: =EFFORT!E36 -> 0 | E36: =MDDI!C36 -> 4 | F36: =SUM(C36:E36) -> 4
A37: 31 | B37: Number of AADHAR cards issued to children | C37: ='EFFORT KMM'!F37 -> 0 | D37: =EFFORT!E37 -> 0 | E37: =MDDI!C37 -> 0 | F37: =SUM(C37:E37) -> 0
A38: 32 | B38: No. of VCPC Meetings Conducted in the existing Committees | C38: ='EFFORT KMM'!F38 -> 2 | D38: =EFFORT!E38 -> 0 | E38: =MDDI!C38 -> 0 | F38: =SUM(C38:E38) -> 2
A39: 33 | B39: Number of Child Protection Committees formed at Village-level (under ICPS) | C39: ='EFFORT KMM'!F39 -> 0 | D39: =EFFORT!E39 -> 0 | E39: =MDDI!C39 -> 0 | F39: =SUM(C39:E39) -> 0
... A42: 36 | B42: Number of Child Marriages Stopped But happened | C42: ='EFFORT KMM'!F42 -> 0 | D42: =EFFORT!E42 -> 0 | E42: =MDDI!C42 -> 0 | F42: =SUM(C42:E42) -> 0
B43: Participation:
...

Sheet APTG
A1: Projects: Pragathi, SRAMA, KDDI, PORD, MDGF, EFFORT and EFFORT Bhadrachalam
A2: Report for the month of: March 2025
A3: Sl. No. | B3: Indicator | C3: March Month Achievement
B4: Education: | C4: AP | D4: TGS | E4: AP/TGS Total
A5: 1 | B5: Number of dropout mainstreamed(6-14 years ) | C5: =AP!G5 -> 0 | D5: =TG!F5 -> 0 | E5: =SUM(C5:D5) -> 0
A6: 2 | B6: Numbe of Dropout Mainstreamed (15-18 years ) | C6: =AP!G6 -> 0 | D6: =TG!F6 -> 0 | E6: =SUM(C6:D6) -> 0
A7: 3 | B7: Number of children received education scholarship | C7: =AP!G7 -> 0 | D7: =TG!F7 -> 0 | E7: =SUM(C7:D7) -> 0
A8: 4 | B8: Number of children appeared for Instant or Supplementary exams (10th and Intermediate) | C8: =AP!G8 -> 286 | D8: =TG!F8 -> 66 | E8: =SUM(C8:D8) -> 352
A9: 5 | B9: Number of children received "Transport Allowance" to attend the school | C9: =AP!G9 -> 0 | D9: =TG!F9 -> 0 | E9: =SUM(C9:D9) -> 0
A10: 6 | B10: Number of children provided with "free bus pass" | C10: =AP!G10 -> 0 | D10: =TG!F10 -> 0 | E10: =SUM(C10:D10) -> 0
A11: 7 | B11: Number of children received free bicycles from the government | C11: =AP!G11 -> 0 | D11: =TG!F11 -> 0 | E11: =SUM(C11:D11) -> 0
B12: School-related indicators:
A13: 8 | B13: Number of schools where additional teachers were appointed | C13: =AP!G13 -> 0 | D13: =TG!F13 -> 0 | E13: =SUM(C13:D13) -> 0
A14: 9 | B14: Number of additional teachers appointed | C14: =AP!G14 -> 0 | D14: =TG!F14 -> 0 | E14: =SUM(C14:D14) -> 0
A15: 10 | B15: Number of schools where new class-rooms were constructed | C15: =AP!G15 -> 0 | D15: =TG!F15 -> 0 | E15: =SUM(C15:D15) -> 0
A16: 11 | B16: Number of schools where new toilets are constructed | C16: =AP!G16 -> 0 | D16: =TG!F16 -> 0 | E16: =SUM(C16:D16) -> 0
A17: 12 | B17: Number of schools where drinking water facilities was created within the premises | C17: =AP!G17 -> 0 | D17: =TG!F17 -> 0 | E17: =SUM(C17:D17) -> 0
A18: 13 | B18: Number of schools where new kitchen shed was constructed | C18: =AP!G18 -> 0 | D18: =TG!F18 -> 0 | E18: =SUM(C18:D18) -> 0
A19: 14 | B19: Number of schools where new ramp was constructed | C19: =AP!G19 -> 0 | D19: =TG!F19 -> 0 | E19: =SUM(C19:D19) -> 0
A20: 15 | B20: Number of schools where play ground facility was created | C20: =AP!G20 -> 0 | D20: =TG!F20 -> 0 | E20: =SUM(C20:D20) -> 0
A21: 16 | B21: Number of schools prevented from closure | C21: =AP!G21 -> 0 | D21: =TG!F21 -> 0 | E21: =SUM(C21:D21) -> 0
A22: 17 | B22: Number of schools upgraded | C22: =AP!G22 -> 0 | D22: =TG!F22 -> 0 | E22: =SUM(C22:D22) -> 0
A23: 18 | B23: Number of schools where class upgradation happened | C23: =AP!G23 -> 0 | D23: =TG!F23 -> 0 | E23: =SUM(C23:D23) -> 0
A24: 19 | B24: Number of ICDS centres which got new buildings (own) | C24: =AP!G24 -> 0 | D24: =TG!F24 -> 0 | E24: =SUM(C24:D24) -> 0
... A26: 21 | B26: No of CBO/ Parents/ SMC meetings conducted | C26: =AP!G26 -> 139 | D26: =TG!F26 -> 20 | E26: =SUM(C26:D26) -> 159
B27: Protection:
A28: 22 | B28: Number of New CL identified (6-14) | C28: =AP!G28 -> 0 | D28: =TG!F28 -> 1 | E28: =SUM(C28:D28) -> 1
A29: 23 | B29: Number of New CL identified (15-18) | C29: =AP!G29 -> 0 | D29: =TG!F29 -> 4 | E29: =SUM(C29:D29) -> 4
A30: 24 | B30: Number of CL rescued with the support from the Police and Labour Departments | C30: =AP!G30 -> 0 | D30: =TG!F30 -> 0 | E30: =SUM(C30:D30) -> 0
A31: 25 | B31: No of CL removed from work using Couselling, home visits, through the support of CBOs, VCPCs PRIs etc. (6-14 Years ) | C31: =AP!G31 -> 15 | D31: =TG!F31 -> 0 | E31: =SUM(C31:D31) -> 15
A32: 26 | B32: No of CL removed from work using Couselling, home visits, through the support of CBOs, VCPCs PRIs etc. (15-18 Years ) | C32: =AP!G32 -> 37 | D32: =TG!F32 -> 0 | E32: =SUM(C32:D32) -> 37
A33: 27 | B33: Number of child labour mainstreamed(6-14) | C33: =AP!G33 -> 0 | D33: =TG!F33 -> 0 | E33: =SUM(C33:D33) -> 0
A34: 28 | B34: Number of CL manstreamed (15-18) | C34: =AP!G34 -> 0 | D34: =TG!F34 -> 0 | E34: =SUM(C34:D34) -> 0
A35: 29 | B35: Number of Birth Certificates issued to 0-1 year children | C35: =AP!G35 -> 27 | D35: =TG!F35 -> 0 | E35: =SUM(C35:D35) -> 27
A36: 30 | B36: Number of Caste Certificates issued to children | C36: =AP!G36 -> 203 | D36: =TG!F36 -> 4 | E36: =SUM(C36:D36) -> 207
A37: 31 | B37: Number of AADHAR cards issued to children | C37: =AP!G37 -> 46 | D37: =TG!F37 -> 0 | E37: =SUM(C37:D37) -> 46
A38: 32 | B38: No. of VCPC Meetings Conducted in the existing Committees | C38: =AP!G38 -> 6 | D38: =TG!F38 -> 2 | E38: =SUM(C38:D38) -> 8
A39: 33 | B39: Number of Child Protection Committees formed at Village-level (under ICPS) | C39: =AP!G39 -> 0 | D39: =TG!F39 -> 0 | E39: =SUM(C39:D39) -> 0
... A42: 36 | B42: Number of Child Marriages Stopped But happened | C42: =AP!G42 -> 3 | D42: =TG!F42 -> 0 | E42: =SUM(C42:D42) -> 3
B43: Participation:
...
